<mujoco model="Human-Skin-Manipulate">
    <include file="scene.xml"/>

    <option timestep="0.002" solver="CG" tolerance="1e-6"/>
    <size nconmax="3000" njmax="10000" nstack="1000000"/>

    <worldbody>
<!--            <geom type="capsule" size="1 1" rgba="1 0 0 1"/>-->
        <body name="Base" pos="0 0 0">
            <geom type="capsule" size="0.03 0.04" rgba=".1 .2 .1 1"/>
            <body name="B3_5" pos="0 0 0.3">
                <geom type="capsule" size="0.01 0.005" rgba=".8 .2 .1 1"/>
                <composite type="cloth" count="10 10 1" spacing="0.03" flatinertia="0.01">
                    <joint kind="main" damping="0.001"/>
                    <skin material="humanskin" texcoord="true" inflate="0.005" subgrid="2"/>
                    <geom type="sphere" size="0.006" rgba=".9 .9 .1 1" />
                </composite>
            <joint name='wr_js' type='hinge' pos='0 0 -0.04' axis='0 1 0' range='-1.57 1.57' damping='10'/>
            </body>
        </body>
    </worldbody>

    <actuator>

		<motor name='a1' 	gear='35' joint='wr_js'/>
<!--    <position ctrllimited="true" ctrlrange="-1.6056 1.6056" joint="wr_js" kp="403.256" name="shoulder_pan_joint"></position>-->
<!--        <position kp="1"/>-->
    </actuator>
</mujoco>